Workbook

Sheet Pivot
A3: Count of ToolNumber | B3: Column Labels
B4: 1 | FG4: 2 | NB4: 3 | NH4: 4 | NP4: Grand Total
A5: Row Labels | B5: .121099KIT | C5: 1.625-ZT-PAD | D5: 1.750INS-DRL | E5: 1/16DRL | F5: 1/2-13-H11-SPRL-FL | G5: 1/2-2FL-CEM | H5: 1/2-4FL-CEM | I5: 1/2SPOTDRL | J5: 1/4-20-2FL-H11-BTM | K5: 1/4-20-GH11-DRAP | L5: 1/4-20-H11-BTM-OSG | M5: 1/4-2FL-BALL-HSSEM | N5: 1/4-2FL-CEM | O5: 1/4DRL | P5: 1/4SPOTDRL | Q5: 10-24 H3 BOTT | R5: 10-24-H11-BTM-OSG | S5: 10-24-H11-PLG | T5: 10PITCHKNURL | U5: 1-1/16-SPADE-INS | V5: 1-1/4-FB-SPADE-INS | W5: 1-1/4-SPADE-INS | X5: 1-1/8-SPADE-INS | Y5: 12.7MMCBD | Z5: 1-5/32BROACH | AA5: 20PITCHKNURL | AB5: 22020S-100L-SPADE | AC5: 23010S-100L-SPADE | AD5: 23020S-125L-SPADE | AE5: 27/64CBD | AF5: 3.250-ZT-PAD-SET1 | AG5: 3.3MMDRL | AH5: 3/16-2FL-BALL-CEM | AI5: 3/16-2FL-CEM | AJ5: 3/32DRL | AK5: 3/4-2FL-W-1/2-SHK | AL5: 3/4DRL | AM5: 3/4SPOTDRL | AN5: 3/8-16-H11-PLG | AO5: 3/8-2FL-CEM | AP5: 3/8DRL | AQ5: 3/8SPOTDRL | AR5: 3/8X90DEG-CHMF | AS5: 3/8X90DEG-CHMF-NECKED | AT5: 4-40-H11-PLG | AU5: 5/16-2FL-CEM | AV5: 5/16DRL | AW5: 5/32-2FL-BALL-CEM | AX5: 5/8-2FL-CEM | AY5: 5/8FEROCIOUS-CEM | AZ5: 59/64-SPADE-INS | BA5: 7/16-2FL-CEM | BB5: 9/16-2FL-CEM | BC5: 9/64DRL | BD5: A12NER2 | BE5: A16NER3 | BF5: A16SVUBR3 | BG5: A20MVUNR3 | BH5: A32NER4 | BI5: A4G0305M03U02GMN | BJ5: ANGT-1623-PPFR3LGJ | BK5: BT-11897-1 | BL5: BT-12340 | BM5: BT-4302-11.5P-3T | BN5: BT-4309-9P-3T | BO5: C12SCLPR3-5 | BP5: C12SCLPR3-6 | BQ5: C12SCLPR3-7 | BR5: C16SCLPR3-4 | BS5: C16SCLPR3-5 | BT5: C16SCLPR3-6 | BU5: C16SCLPR3-7 | BV5: C6SCLPR2 | BW5: C8SCLPR3-5 | BX5: CB2B | BY5: CCGX-3251AL | BZ5: CNGP431 | CA5: CNGP432 | CB5: CNMG431 | CC5: CNMG432MLK10 | CD5: CNMG432MP-BRASS | CE5: CNMS432 | CF5: CPMT2151LF | CG5: CPMT3250.5LF | CH5: CPMT32505LF | CI5: CPMT3251LF | CJ5: CPMT3252LF | CK5: CPMT3252LF-CAP | CL5: CT-5248-22 | CM5: DA-LIVE-Z-HEAD | CN5: DCLNR164DKC | CO5: DGFH32-3 | CP5: DGNM-3202C | CQ5: DORTO1MS-10-C | CR5: DVJNL163C | CS5: DVJNR163DKC3 | CT5: E16SCLPR3 | CU5: EG125I03U05GUN | CV5: ER40-COLLET-SET | CW5: EVM50R0312MC | CX5: EVM50R0316MC | CY5: GFG125CC | CZ5: HARD-JAWS-STD | DA5: ISCAR FACE GROOVE INSERT | DB5: ISCAR INT FACE GROOVE BLADE #7 | DC5: ISCAR INT RH FACE GROOVE BAR | DD5: ISCAR-GRIP-3002Y | DE5: ISCAR-SGTBU-CUTOFF | DF5: KGMSR1650N | DG5: KIPR125XD-ENDMILL | DH5: LIVE-X | DI5: LIVE-Z | DJ5: LSASR163-LAYDN-THD | DK5: LT16ER18UN | DL5: MCHR-218-126 | DM5: MCHR-235-101 | DN5: MCHR-506-101-20 | DO5: MCHR-507-231-33 | DP5: MCHR-510-117-36 | DQ5: N01138 | DR5: NG3062LK | DS5: NG3062RK | DT5: NG3094LK KC5010 | DU5: NG3094RK | DV5: NG3125L | DW5: NG3125LK | DX5: NG3125R | DY5: NG3125RK | DZ5: NG3189RK | EA5: NO.05DRL | EB5: NO.21DRL | EC5: NO.23DRL | ED5: NO.2SMDRL | EE5: NO.30CBD | EF5: NR3062L | EG5: NR3062R | EH5: NSL163C | EI5: NSR163C | EJ5: NT3L | EK5: NT3R | EL5: NTP2L | EM5: NTP3L | EN5: NTP3R | EO5: NWC-3R11E | EP5: S16T-SCLCR | EQ5: SOLID-ID-BLOCK | ER5: SSO75ER16700 | ES5: STOPBLOCK1250 | ET5: STOPBLOCK2.250 | EU5: STOPBLOCK750 | EV5: T610 | EW5: TLGP-3125R | EX5: TLTP3L | EY5: TLTP3R | EZ5: VAL100XTN | FA5: VNGP330.5 | FB5: VNMG332 | FC5: VNMS332 | FD5: VNMS-332 | FE5: X6030000X012080 | FF5: ZT-COLLET-PADS | FG5: 1/16DRL | FH5: 1/2-20-H11-PLG | FI5: 1/2-2FL-CEM | FJ5: 1/2SPOTDRL | FK5: 1/4-20-2FL-H11-BTM | FL5: 1/4-20-H11-BTM-OSG | FM5: 1/4-2FL-CEM | FN5: 1/4SPOTDRL | FO5: 1/8-2FL-CEM | FP5: 102257J | FQ5: 10-24GH11EXT-BTM | FR5: 10-24-SPLK-2FL-PLG-TAP | FS5: 1056 | FT5: 119400L | FU5: 120308L | FV5: 121099J | FW5: 124296L | FX5: 29/64DRL | FY5: 3.3MMDRL | FZ5: 3/16-2FL-BALL-CEM | GA5: 3/16-2FL-CEM | GB5: 3/16CBT-DRL | GC5: 3/16DRL | GD5: 3/16SPOTDRL | GE5: 3/32DRL | GF5: 3/4SPOTDRL | GG5: 3/8-2FL-CEM | GH5: 3/8SPOTDRL | GI5: 3/8X90DEG-CHMF | GJ5: 4-40-H11-PLG | GK5: 5/16-2FL-CEM | GL5: 5/32-2FL-BALL-CEM | GM5: 7/16-2FL-CEM | GN5: 9/32CBT-DRL | GO5: A12NER2 | GP5: A12SSDUPR3 | GQ5: A16NER3 | GR5: A4G0405M04U04GMN | GS5: A4G0405M04U08GMN | GT5: A4M50R0414M | GU5: AC205 | GV5: AC2110 | GW5: AC2310 | GX5: AC2410 | GY5: AC2510 | GZ5: AC2610 | HA5: AC2710 | HB5: AC310 | HC5: AC403 | HD5: AC409 | HE5: AC410 | HF5: AC509 | HG5: AC513 | HH5: AC601 | HI5: AC602 | HJ5: AC604 | HK5: AC606 | HL5: AC608 | HM5: AC610 | HN5: AC612 | HO5: AC614 | HP5: AC701 | HQ5: AC702 | HR5: AC703 | HS5: AC704 | HT5: AC705 | HU5: AC707 | HV5: AC708 | HW5: AC710 | HX5: AC712 | HY5: AC715 | HZ5: AC717 | IA5: AC719 | IB5: AC727 | IC5: ANGT1623PPFR3LGJ | ID5: ASSTRINGS | IE5: BT-12340 | IF5: BT-12723 | IG5: BT-12804L | IH5: BT-12805L | II5: BT-1947-3 | IJ5: BT-4014-2-B | IK5: BT-4302-11.5P-3T | IL5: BT-4317-8P-4T | IM5: BT-5365-11P-3T | IN5: C10SCLPR2-4 | IO5: C10SCLPR3-7 | IP5: C12SCLPR3-4 | IQ5: C12SCLPR3-5 | IR5: C12SCLPR3-7 | IS5: C16SCLPR3-4 | IT5: C16SCLPR3-5 | IU5: C16SCLPR3-6 | IV5: C16SCLPR3-7 | IW5: C4SCLDR2 | IX5: CDCD-51-C25 | IY5: CNGP431 | IZ5: CNMG431 | JA5: CNMG432MLK10 | JB5: CNMS432 | JC5: CPMT2151LF | JD5: CPMT3250.5LF | JE5: CPMT3251LF | JF5: CPMT3252LF | JG5: CPMT3252LF-CAP | JH5: CT-11409 | JI5: CT-6002-17 | JJ5: CT-6002-3 | JK5: CT-6002-4 | JL5: CT-6003-13 | JM5: CT-6003-23 | JN5: CT-6003-24 | JO5: CT-6003-7 | JP5: CT-6004-19 | JQ5: CT-6004-2 | JR5: CT-6004-23 | JS5: CT-6004-24 | JT5: CT-6004-26 | JU5: CT-6004-27 | JV5: CT-6004-29 | JW5: CT-6004-37-NTX | JX5: CT-6004-40 | JY5: CT-6004-46 | JZ5: CT-6004-50 | KA5: CT-6004-6 | KB5: DA-LIVE-Z-HEAD | KC5: DCLNR164DKC | KD5: DGFH32-3 | KE5: DGNM-3202C | KF5: DPMT3251LF | KG5: DT-11628 | KH5: DT-11877 | KI5: DT-12680L | KJ5: DT-12724L | KK5: DT-12875L | KL5: DT-13131 | KM5: DT-13596 | KN5: DT-13596-A- | KO5: DT-13597 | KP5: DT-13885-NTX | KQ5: dt-13946L | KR5: DT-13949 | KS5: DVJNL163C | KT5: DVJNR163DKC3 | KU5: E16NER3 | KV5: E16SCLPR3 | KW5: E4M-SCLDR1.2 | KX5: ER32-COLLET | KY5: ER40-COLLET-SET | KZ5: EXTENSIONS | LA5: ISCAR-HAPR25.4C | LB5: ISCAR-HGAER-ADPT | LC5: ISCAR-HPGL-3003Y | LD5: ISCAR-SGTBU-CUTOFF | LE5: KGMSR1650N | LF5: KIPR125XD-ENDMILL | LG5: LIVE-X | LH5: LIVE-Z | LI5: LSASR16 | LJ5: LSASR163-LAYDN-THD | LK5: LSASR18 | LL5: LT16ER12UN | LM5: LT16ER16UN | LN5: LT16ER18UN | LO5: LTR.L.DRL | LP5: LTR.T.DRL | LQ5: MB-0393 | LR5: NG2031L | LS5: NG2047L | LT5: NG2062LK | LU5: NG2125LK | LV5: NG3047R | LW5: NG3062LK | LX5: NG3062R | LY5: NG3062RK | LZ5: NG3094RK | MA5: NG3125LK | MB5: NG3125RK | MC5: NO.05DRL | MD5: NO.10DRL | ME5: NO.21DRL | MF5: NO.23EXL-DRL | MG5: NO.27DRL | MH5: NO.30CBD-DRL | MI5: NO.41DRL | MJ5: NO.42DRL | MK5: NR3062L | ML5: NR3062R | MM5: NSL162C | MN5: NSL163C | MO5: NSR163C | MP5: NT3L | MQ5: NT3R | MR5: NTP2L | MS5: NTP3L | MT5: P-404-CONICAL | MU5: RJ1008 | MV5: RJ1010 | MW5: SOLID-ID-BLOCK | MX5: VNGP330.5 | MY5: VNMG332MP | MZ5: VNMS332 | NA5: VNMS-332 | NB5: CNMG431 | NC5: DCLNR164DKC | ND5: DGFH32-3 | NE5: DGNM-3202C | NF5: ISCAR-SGTBU-CUTOFF | NG5: ZT-COLLET-PADS | NH5: 1/4-2FL-CEM | NI5: 3/16SPOTDRL | NJ5: CNMS432 | NK5: DCLNR164DKC | NL5: LIVE-X | NM5: LIVE-Z | NN5: NO.30CBD-DRL | NO5: RJ1008
A6: 101759a | BZ6: 1 | CN6: 1 | CO6: 1 | CP6: 1 | DE6: 1 | FJ6: 1 | GD6: 1 | IY6: 1 | KC6: 1 | LQ6: 1 | MG6: 1 | NP6: 11
A7: 102088 | BE7: 4 | BR7: 2 | CE7: 2 | CJ7: 2 | CN7: 2 | CO7: 2 | CP7: 2 | CY7: 1 | DA7: 1 | DB7: 1 | DC7: 1 | DE7: 2 | DJ7: 2 | DK7: 2 | DM7: 1 | DW7: 2 | DY7: 2 | EI7: 2 | EM7: 2 | FF7: 2 | FG7: 2 | FN7: 2 | GC7: 2 | GY7: 2 | HG7: 2 | IT7: 2 | JB7: 2 | JF7: 2 | JK7: 2 | KC7: 2 | KG7: 2 | LH7: 6 | LY7: 2 | MO7: 2 | NP7: 69
A8: 102097 | BE8: 2 | BX8: 1 | BY8: 1 | CD8: 1 | CN8: 1 | CY8: 1 | CZ8: 1 | DM8: 1 | DQ8: 1 | EI8: 2 | EP8: 1 | EV8: 1 | EW8: 1 | EX8: 1 | EY8: 1 | FG8: 1 | FN8: 1 | FO8: 1 | GC8: 1 | GY8: 1 | HG8: 1 | IT8: 1 | JB8: 1 | JF8: 1 | JK8: 1 | KC8: 1 | KD8: 1 | KE8: 1 | KH8: 1 | LD8: 1 | LH8: 4 | LJ8: 1 | LN8: 1 | LY8: 1 | MO8: 1 | NP8: 40
A9: 102258 | BQ9: 1 | CE9: 1 | CJ9: 1 | CN9: 1 | DX9: 1 | EI9: 1 | ET9: 1 | GZ9: 1 | HL9: 1 | IR9: 1 | JB9: 1 | JF9: 1 | JP9: 1 | JQ9: 1 | KC9: 1 | KG9: 1 | LG9: 3 | LH9: 3 | LX9: 1 | MO9: 2 | MQ9: 1 | NP9: 26
A10: 104403 | CB10: 1 | CN10: 1 | CO10: 1 | CP10: 1 | DE10: 1 | FF10: 1 | FM10: 1 | GD10: 1 | JB10: 1 | KC10: 1 | LG10: 2 | LH10: 1 | MH10: 1 | MU10: 1 | NP10: 15
A11: 104430 | NB11: 1 | NC11: 1 | ND11: 1 | NE11: 1 | NF11: 1 | NG11: 1 | NH11: 1 | NI11: 1 | NJ11: 1 | NK11: 1 | NL11: 2 | NM11: 1 | NN11: 1 | NO11: 1 | NP11: 15
A12: 106939 | I12: 1 | J12: 1 | BE12: 1 | BO12: 1 | CE12: 1 | CI12: 1 | CN12: 1 | CO12: 1 | CP12: 1 | CQ12: 1 | CV12: 3 | DE12: 1 | DH12: 3 | EA12: 1 | EF12: 1 | HA12: 1 | HU12: 1 | IE12: 1 | IP12: 1 | JB12: 1 | JF12: 1 | JZ12: 1 | KC12: 1 | KG12: 1 | LH12: 1 | NP12: 29
A13: 108314 | I13: 1 | L13: 1 | T13: 1 | BE13: 1 | BQ13: 1 | CE13: 1 | CI13: 1 | CN13: 1 | DH13: 3 | EA13: 1 | EG13: 1 | GQ13: 2 | HA13: 1 | HU13: 1 | IR13: 1 | JB13: 1 | JF13: 1 | JU13: 1 | KC13: 1 | LW13: 1 | MP13: 1 | NP13: 24
A14: 108354 | B14: 1 | F14: 1 | I14: 1 | L14: 1 | AE14: 1 | AK14: 1 | AM14: 1 | CE14: 1 | CN14: 1 | DH14: 4 | DI14: 3 | DX14: 1 | EA14: 1 | EI14: 1 | FJ14: 1 | FV14: 1 | JB14: 1 | KC14: 1 | LA14: 1 | LB14: 1 | LC14: 1 | MW14: 1 | NP14: 27
A15: 116344 | BL15: 1 | BT15: 1 | CI15: 1 | CO15: 1 | CP15: 1 | CS15: 1 | DE15: 1 | DI15: 1 | FC15: 1 | FI15: 1 | GQ15: 2 | GZ15: 1 | HH15: 1 | IG15: 1 | IQ15: 1 | IZ15: 1 | JF15: 1 | KC15: 1 | KG15: 1 | LG15: 1 | MA15: 1 | MS15: 1 | NP15: 23
A16: 116811 | AA16: 1 | AC16: 1 | AZ16: 1 | BD16: 2 | BQ16: 1 | CJ16: 1 | CR16: 1 | CS16: 1 | DN16: 1 | DO16: 1 | DT16: 1 | EL16: 1 | EQ16: 1 | FB16: 1 | FC16: 1 | GQ16: 1 | GX16: 1 | HC16: 1 | IE16: 1 | IR16: 1 | JB16: 1 | JF16: 1 | KC16: 1 | LH16: 1 | MA16: 1 | MB16: 1 | MO16: 1 | NP16: 28
A17: 117425 | BS17: 1 | CE17: 1 | CJ17: 1 | CN17: 1 | CO17: 1 | CP17: 1 | CR17: 1 | DE17: 1 | FC17: 1 | FF17: 1 | FJ17: 1 | FK17: 1 | GQ17: 1 | HA17: 1 | HU17: 1 | IQ17: 1 | JB17: 1 | JF17: 1 | JS17: 1 | KC17: 1 | KG17: 1 | KY17: 3 | LG17: 3 | MC17: 1 | MK17: 1 | NP17: 29
A18: 117481 | U18: 1 | AA18: 1 | AB18: 1 | BE18: 1 | BN18: 1 | BP18: 1 | CE18: 1 | CJ18: 1 | CN18: 1 | CO18: 1 | CP18: 1 | DE18: 1 | DI18: 1 | DW18: 1 | EQ18: 1 | IK18: 1 | IN18: 1 | JC18: 1 | KS18: 1 | KT18: 1 | LH18: 1 | MV18: 1 | MZ18: 1 | NA18: 1 | NP18: 24
A19: 118516 | AI19: 1 | AJ19: 1 | AQ19: 1 | AT19: 1 | BE19: 1 | BF19: 1 | BH19: 1 | BU19: 1 | CE19: 1 | CJ19: 1 | CN19: 1 | CO19: 1 | CP19: 1 | CU19: 1 | CW19: 1 | DE19: 1 | DF19: 1 | DH19: 4 | DT19: 1 | FC19: 1 | FE19: 1 | FF19: 1 | FN19: 1 | GE19: 1 | GJ19: 1 | GO19: 1 | GR19: 1 | GT19: 1 | HA19: 1 | HX19: 1 | IV19: 1 | JB19: 1 | JE19: 1 | JW19: 1 | KC19: 1 | LE19: 1 | LH19: 3 | LS19: 1 | LW19: 1 | MN19: 1 | NP19: 45
A20: 118875 | AF20: 1 | BT20: 1 | CJ20: 1 | CS20: 1 | DS20: 1 | EI20: 1 | FC20: 1 | GM20: 1 | HA20: 1 | HY20: 1 | IU20: 1 | JF20: 1 | KT20: 1 | LG20: 1 | MZ20: 1 | NP20: 15
A21: 119400 | P21: 1 | Q21: 1 | AL21: 1 | BW21: 1 | CC21: 1 | CJ21: 1 | CN21: 1 | DI21: 3 | EB21: 1 | EQ21: 1 | FT21: 1 | GW21: 1 | HB21: 1 | IO21: 1 | JA21: 1 | JF21: 1 | KC21: 1 | KT21: 1 | MO21: 1 | MQ21: 1 | MY21: 1 | NP21: 23
A22: 119887 | P22: 1 | AG22: 1 | AX22: 1 | BG22: 1 | BT22: 1 | CB22: 1 | CJ22: 1 | CN22: 1 | CO22: 1 | CP22: 1 | CV22: 3 | DE22: 1 | DH22: 3 | FD22: 1 | FN22: 1 | GJ22: 1 | GS22: 1 | GT22: 1 | HA22: 1 | HT22: 1 | IS22: 1 | JB22: 1 | JF22: 1 | JR22: 1 | KC22: 1 | KG22: 1 | KX22: 1 | KY22: 2 | LE22: 1 | LH22: 3 | LT22: 1 | MI22: 1 | MM22: 1 | NP22: 40
A23: 119927 | H23: 1 | U23: 1 | AB23: 1 | AM23: 1 | BO23: 1 | CE23: 1 | CI23: 1 | CM23: 3 | CN23: 1 | DL23: 1 | DP23: 1 | ED23: 1 | EQ23: 1 | FJ23: 1 | GN23: 1 | HA23: 1 | HV23: 1 | IV23: 1 | IZ23: 1 | JF23: 1 | KB23: 2 | KC23: 1 | KK23: 1 | NP23: 26
A24: 120308 | P24: 1 | AG24: 1 | AU24: 1 | BE24: 1 | BS24: 1 | CE24: 1 | CJ24: 1 | CN24: 1 | CO24: 1 | CP24: 1 | CV24: 3 | DE24: 1 | DH24: 2 | DR24: 1 | DS24: 1 | EI24: 1 | FF24: 1 | FU24: 1 | GP24: 1 | HA24: 1 | HR24: 1 | JB24: 1 | KC24: 1 | KF24: 1 | KG24: 1 | KT24: 1 | MO24: 1 | MQ24: 1 | MZ24: 1 | NP24: 32
A25: 120337 | CJ25: 1 | CO25: 1 | CP25: 1 | CS25: 1 | CT25: 1 | DE25: 1 | EI25: 1 | EK25: 1 | FC25: 1 | FI25: 1 | GQ25: 1 | GZ25: 1 | HM25: 1 | IF25: 1 | JB25: 1 | JF25: 1 | JM25: 1 | KC25: 1 | KV25: 1 | MA25: 1 | NP25: 20
A26: 120522 | CJ26: 1 | CO26: 1 | CP26: 1 | CS26: 1 | CT26: 1 | DE26: 1 | EI26: 1 | EK26: 1 | FC26: 1 | FI26: 1 | GQ26: 1 | GZ26: 1 | HM26: 1 | IL26: 1 | JB26: 1 | JF26: 1 | JM26: 1 | KC26: 1 | KV26: 1 | MA26: 1 | NP26: 20
A27: 120698 | AR27: 1 | AU27: 1 | BS27: 1 | CE27: 1 | CJ27: 1 | CN27: 1 | CO27: 1 | CP27: 1 | DE27: 1 | DH27: 2 | DS27: 1 | EI27: 1 | FF27: 1 | FN27: 1 | FY27: 1 | GB27: 1 | GG27: 1 | GZ27: 1 | HM27: 1 | IH27: 1 | IQ27: 1 | JB27: 1 | JF27: 1 | KC27: 1 | KG27: 1 | KX27: 1 | KY27: 3 | LG27: 3 | LH27: 1 | LJ27: 1 | LM27: 1 | MB27: 1 | MO27: 1 | NP27: 38
A28: 120699 | E28: 1 | P28: 1 | S28: 1 | BO28: 1 | CE28: 1 | CI28: 1 | CN28: 1 | CO28: 1 | CP28: 1 | CQ28: 1 | CV28: 4 | DE28: 1 | DH28: 4 | EC28: 1 | HA28: 1 | IB28: 1 | IP28: 1 | JB28: 1 | JF28: 1 | JY28: 1 | KC28: 1 | KG28: 1 | MB28: 1 | MO28: 1 | NP28: 30
A29: 120708 | M29: 1 | N29: 1 | P29: 1 | U29: 1 | AB29: 1 | AG29: 1 | BO29: 1 | CE29: 1 | CJ29: 1 | CN29: 1 | CO29: 1 | CP29: 1 | DE29: 1 | DH29: 3 | DS29: 1 | EI29: 1 | EQ29: 1 | FF29: 1 | FM29: 1 | GB29: 1 | GL29: 1 | GX29: 1 | HD29: 1 | IQ29: 1 | JB29: 1 | JD29: 1 | KC29: 1 | KG29: 1 | KT29: 1 | LG29: 2 | LH29: 1 | LJ29: 1 | LL29: 1 | MX29: 1 | NP29: 37
A30: 120709 | N30: 1 | U30: 1 | AB30: 1 | AW30: 1 | BP30: 1 | CE30: 1 | CJ30: 1 | CN30: 1 | CO30: 1 | CP30: 1 | DE30: 1 | DH30: 2 | DS30: 1 | EI30: 1 | FF30: 1 | FM30: 1 | FN30: 1 | FY30: 1 | GC30: 1 | GX30: 1 | HE30: 1 | IQ30: 1 | JB30: 1 | JD30: 1 | KC30: 1 | KG30: 1 | KT30: 1 | LG30: 3 | LH30: 1 | LJ30: 1 | LL30: 1 | MX30: 1 | NP30: 35
A31: 120722 | AH31: 1 | AO31: 1 | AR31: 1 | AU31: 1 | BO31: 1 | CE31: 1 | CI31: 1 | CN31: 1 | CO31: 1 | CP31: 1 | DE31: 1 | DH31: 4 | DS31: 1 | EI31: 1 | FF31: 1 | FN31: 1 | FY31: 1 | GB31: 1 | GK31: 1 | GZ31: 1 | HM31: 1 | IH31: 1 | IQ31: 1 | JB31: 1 | JF31: 1 | KC31: 1 | KG31: 1 | LG31: 3 | LH31: 1 | LJ31: 1 | LM31: 1 | MB31: 1 | MO31: 1 | NP31: 38
A32: 120730 | Z32: 1 | BQ32: 1 | CE32: 1 | CJ32: 1 | CN32: 1 | CO32: 1 | CP32: 1 | DE32: 1 | DY32: 1 | EG32: 1 | EI32: 2 | EQ32: 1 | FN32: 1 | FR32: 1 | GQ32: 2 | GZ32: 1 | HI32: 1 | IR32: 1 | JB32: 1 | JF32: 1 | KC32: 1 | KJ32: 1 | LG32: 3 | MA32: 1 | ME32: 1 | MS32: 1 | NP32: 30
A33: 120738 | E33: 1 | P33: 1 | S33: 1 | BO33: 1 | CE33: 1 | CI33: 1 | CN33: 1 | CO33: 1 | CP33: 1 | CQ33: 1 | CV33: 4 | DE33: 1 | DH33: 4 | EC33: 1 | HA33: 1 | IA33: 1 | IP33: 1 | JB33: 1 | JF33: 1 | JT33: 1 | KC33: 1 | KG33: 1 | MB33: 1 | MO33: 1 | NP33: 30
A34: 120739 | AR34: 1 | AU34: 1 | BP34: 2 | CE34: 1 | CG34: 1 | CJ34: 1 | CN34: 1 | CO34: 1 | CP34: 1 | DE34: 1 | DH34: 2 | DS34: 1 | EI34: 1 | FF34: 1 | FN34: 1 | FY34: 1 | GB34: 1 | GG34: 1 | GZ34: 1 | HL34: 1 | IQ34: 1 | JB34: 1 | JD34: 1 | KC34: 1 | KG34: 1 | KT34: 1 | LG34: 3 | LH34: 1 | LJ34: 1 | LN34: 1 | MB34: 1 | MO34: 1 | MX34: 1 | NP34: 37
A35: 120742 | P35: 1 | AG35: 1 | AX35: 1 | BS35: 2 | CB35: 1 | CI35: 1 | CJ35: 1 | CN35: 1 | CO35: 1 | CP35: 1 | DE35: 1 | DH35: 3 | FN35: 1 | GJ35: 1 | GR35: 1 | GT35: 1 | HA35: 1 | HT35: 1 | IP35: 1 | JB35: 1 | JF35: 1 | JL35: 1 | KC35: 1 | KG35: 1 | LE35: 1 | LH35: 3 | LT35: 1 | MI35: 1 | MM35: 1 | NP35: 34
A36: 120744 | P36: 1 | S36: 1 | BO36: 1 | CE36: 1 | CI36: 1 | CN36: 1 | CO36: 1 | CP36: 1 | CQ36: 1 | CV36: 3 | DE36: 1 | DH36: 3 | EC36: 1 | HA36: 1 | HS36: 1 | IP36: 1 | JB36: 1 | JF36: 1 | JX36: 1 | KC36: 1 | KG36: 1 | MB36: 1 | MO36: 1 | NP36: 27
A37: 120745 | P37: 1 | AY37: 1 | BT37: 2 | CA37: 1 | CI37: 1 | CJ37: 1 | CN37: 1 | CO37: 1 | CP37: 1 | CS37: 1 | CV37: 3 | DE37: 1 | DH37: 3 | EE37: 1 | FA37: 1 | FN37: 1 | GJ37: 1 | GS37: 1 | GT37: 1 | GZ37: 1 | HN37: 1 | IS37: 1 | IZ37: 1 | JF37: 1 | JN37: 1 | KC37: 1 | KG37: 1 | KX37: 1 | KY37: 2 | LE37: 1 | LH37: 3 | LT37: 1 | MI37: 1 | MM37: 1 | NP37: 42
A38: 120996 | AH38: 1 | AR38: 1 | AU38: 1 | BA38: 1 | BO38: 1 | BS38: 1 | CE38: 1 | CI38: 1 | CJ38: 1 | CN38: 1 | CO38: 1 | CP38: 1 | DE38: 1 | DH38: 4 | DS38: 1 | EI38: 1 | FF38: 1 | FN38: 1 | FY38: 1 | GC38: 1 | GG38: 1 | GZ38: 1 | HM38: 1 | IH38: 1 | IQ38: 1 | JB38: 1 | JF38: 1 | KC38: 1 | KG38: 1 | KT38: 1 | LG38: 3 | LH38: 1 | LJ38: 1 | LM38: 1 | MB38: 1 | MO38: 1 | MX38: 1 | NP38: 42
A39: 121341 | BS39: 1 | CE39: 1 | CJ39: 1 | CN39: 1 | CO39: 1 | CP39: 1 | CR39: 1 | DE39: 1 | FC39: 1 | FF39: 1 | FJ39: 1 | FK39: 1 | GQ39: 1 | HA39: 1 | HU39: 1 | IQ39: 1 | JB39: 1 | JF39: 1 | JS39: 1 | KC39: 1 | KG39: 1 | KY39: 3 | LG39: 3 | MC39: 1 | MK39: 1 | NP39: 29
A40: 122057 | P40: 1 | AG40: 1 | AH40: 1 | AU40: 1 | BA40: 1 | BE40: 1 | BS40: 1 | CE40: 1 | CJ40: 1 | CN40: 1 | CO40: 1 | CP40: 1 | DE40: 1 | DH40: 4 | DR40: 1 | DS40: 1 | EI40: 1 | FF40: 1 | FU40: 1 | GP40: 1 | HA40: 1 | HR40: 1 | JB40: 1 | KC40: 1 | KF40: 1 | KG40: 1 | KT40: 1 | MO40: 1 | MQ40: 1 | MZ40: 1 | NP40: 33
A41: 122174 | BS41: 1 | CE41: 1 | CJ41: 1 | CN41: 1 | CO41: 1 | CP41: 1 | DE41: 1 | FF41: 1 | FJ41: 1 | FK41: 1 | GQ41: 1 | GY41: 1 | HG41: 1 | IQ41: 1 | IZ41: 1 | JF41: 1 | KC41: 1 | KG41: 1 | LG41: 3 | LV41: 1 | MC41: 1 | MK41: 1 | MO41: 1 | NP41: 25
A42: 122236 | K42: 1 | X42: 1 | Y42: 1 | AB42: 1 | AR42: 1 | AX42: 1 | BE42: 2 | BJ42: 1 | BK42: 1 | BO42: 1 | CE42: 1 | CJ42: 1 | CN42: 1 | DG42: 1 | DH42: 5 | DI42: 1 | DL42: 1 | DP42: 1 | DT42: 1 | EM42: 1 | EQ42: 1 | ER42: 1 | FF42: 1 | FM42: 1 | IC42: 1 | IW42: 1 | JB42: 1 | JC42: 1 | KC42: 1 | KL42: 1 | KZ42: 1 | LF42: 1 | LG42: 1 | LH42: 1 | LJ42: 1 | LN42: 1 | LP42: 1 | MB42: 1 | MO42: 1 | NP42: 44
...

Sheet Binary
A1: Row Labels | B1: .121099KIT | C1: 1.625-ZT-PAD | D1: 1.750INS-DRL | E1: 1/16DRL | F1: 1/2-13-H11-SPRL-FL | G1: 1/2-2FL-CEM | H1: 1/2-4FL-CEM | I1: 1/2SPOTDRL | J1: 1/4-20-2FL-H11-BTM | K1: 1/4-20-GH11-DRAP | L1: 1/4-20-H11-BTM-OSG | M1: 1/4-2FL-BALL-HSSEM | N1: 1/4-2FL-CEM | O1: 1/4DRL | P1: 1/4SPOTDRL | Q1: 10-24 H3 BOTT | R1: 10-24-H11-BTM-OSG | S1: 10-24-H11-PLG | T1: 10PITCHKNURL | U1: 1-1/16-SPADE-INS | V1: 1-1/4-FB-SPADE-INS | W1: 1-1/4-SPADE-INS | X1: 1-1/8-SPADE-INS | Y1: 12.7MMCBD | Z1: 1-5/32BROACH | AA1: 20PITCHKNURL | AB1: 22020S-100L-SPADE | AC1: 23010S-100L-SPADE | AD1: 23020S-125L-SPADE | AE1: 27/64CBD | AF1: 3.250-ZT-PAD-SET1 | AG1: 3.3MMDRL | AH1: 3/16-2FL-BALL-CEM | AI1: 3/16-2FL-CEM | AJ1: 3/32DRL | AK1: 3/4-2FL-W-1/2-SHK | AL1: 3/4DRL | AM1: 3/4SPOTDRL | AN1: 3/8-16-H11-PLG | AO1: 3/8-2FL-CEM | AP1: 3/8DRL | AQ1: 3/8SPOTDRL | AR1: 3/8X90DEG-CHMF | AS1: 3/8X90DEG-CHMF-NECKED | AT1: 4-40-H11-PLG | AU1: 5/16-2FL-CEM | AV1: 5/16DRL | AW1: 5/32-2FL-BALL-CEM | AX1: 5/8-2FL-CEM | AY1: 5/8FEROCIOUS-CEM | AZ1: 59/64-SPADE-INS | BA1: 7/16-2FL-CEM | BB1: 9/16-2FL-CEM | BC1: 9/64DRL | BD1: A12NER2 | BE1: A16NER3 | BF1: A16SVUBR3 | BG1: A20MVUNR3 | BH1: A32NER4 | BI1: A4G0305M03U02GMN | BJ1: ANGT-1623-PPFR3LGJ | BK1: BT-11897-1 | BL1: BT-12340 | BM1: BT-4302-11.5P-3T | BN1: BT-4309-9P-3T | BO1: C12SCLPR3-5 | BP1: C12SCLPR3-6 | BQ1: C12SCLPR3-7 | BR1: C16SCLPR3-4 | BS1: C16SCLPR3-5 | BT1: C16SCLPR3-6 | BU1: C16SCLPR3-7 | BV1: C6SCLPR2 | BW1: C8SCLPR3-5 | BX1: CB2B | BY1: CCGX-3251AL | BZ1: CNGP431 | CA1: CNGP432 | CB1: CNMG431 | CC1: CNMG432MLK10 | CD1: CNMG432MP-BRASS | CE1: CNMS432 | CF1: CPMT2151LF | CG1: CPMT3250.5LF | CH1: CPMT32505LF | CI1: CPMT3251LF | CJ1: CPMT3252LF | CK1: CPMT3252LF-CAP | CL1: CT-5248-22 | CM1: DA-LIVE-Z-HEAD | CN1: DCLNR164DKC | CO1: DGFH32-3 | CP1: DGNM-3202C | CQ1: DORTO1MS-10-C | CR1: DVJNL163C | CS1: DVJNR163DKC3 | CT1: E16SCLPR3 | CU1: EG125I03U05GUN | CV1: ER40-COLLET-SET | CW1: EVM50R0312MC | CX1: EVM50R0316MC | CY1: GFG125CC | CZ1: HARD-JAWS-STD | DA1: ISCAR FACE GROOVE INSERT | DB1: ISCAR INT FACE GROOVE BLADE #7 | DC1: ISCAR INT RH FACE GROOVE BAR | DD1: ISCAR-GRIP-3002Y | DE1: ISCAR-SGTBU-CUTOFF | DF1: KGMSR1650N | DG1: KIPR125XD-ENDMILL | DH1: LIVE-X | DI1: LIVE-Z | DJ1: LSASR163-LAYDN-THD | DK1: LT16ER18UN | DL1: MCHR-218-126 | DM1: MCHR-235-101 | DN1: MCHR-506-101-20 | DO1: MCHR-507-231-33 | DP1: MCHR-510-117-36 | DQ1: N01138 | DR1: NG3062LK | DS1: NG3062RK | DT1: NG3094LK KC5010 | DU1: NG3094RK | DV1: NG3125L | DW1: NG3125LK | DX1: NG3125R | DY1: NG3125RK | DZ1: NG3189RK | EA1: NO.05DRL | EB1: NO.21DRL | EC1: NO.23DRL | ED1: NO.2SMDRL | EE1: NO.30CBD | EF1: NR3062L | EG1: NR3062R | EH1: NSL163C | EI1: NSR163C | EJ1: NT3L | EK1: NT3R | EL1: NTP2L | EM1: NTP3L | EN1: NTP3R | EO1: NWC-3R11E | EP1: S16T-SCLCR | EQ1: SOLID-ID-BLOCK | ER1: SSO75ER16700 | ES1: STOPBLOCK1250 | ET1: STOPBLOCK2.250 | EU1: STOPBLOCK750 | EV1: T610 | EW1: TLGP-3125R | EX1: TLTP3L | EY1: TLTP3R | EZ1: VAL100XTN | FA1: VNGP330.5 | FB1: VNMG332 | FC1: VNMS332 | FD1: VNMS-332 | FE1: X6030000X012080 | FF1: ZT-COLLET-PADS | FG1: 1/16DRL | FH1: 1/2-20-H11-PLG | FI1: 1/2-2FL-CEM | FJ1: 1/2SPOTDRL | FK1: 1/4-20-2FL-H11-BTM | FL1: 1/4-20-H11-BTM-OSG | FM1: 1/4-2FL-CEM | FN1: 1/4SPOTDRL | FO1: 1/8-2FL-CEM | FP1: 102257J | FQ1: 10-24GH11EXT-BTM | FR1: 10-24-SPLK-2FL-PLG-TAP | FS1: 1056 | FT1: 119400L | FU1: 120308L | FV1: 121099J | FW1: 124296L | FX1: 29/64DRL | FY1: 3.3MMDRL | FZ1: 3/16-2FL-BALL-CEM | GA1: 3/16-2FL-CEM | GB1: 3/16CBT-DRL | GC1: 3/16DRL | GD1: 3/16SPOTDRL | GE1: 3/32DRL | GF1: 3/4SPOTDRL | GG1: 3/8-2FL-CEM | GH1: 3/8SPOTDRL | GI1: 3/8X90DEG-CHMF | GJ1: 4-40-H11-PLG | GK1: 5/16-2FL-CEM | GL1: 5/32-2FL-BALL-CEM | GM1: 7/16-2FL-CEM | GN1: 9/32CBT-DRL | GO1: A12NER2 | GP1: A12SSDUPR3 | GQ1: A16NER3 | GR1: A4G0405M04U04GMN | GS1: A4G0405M04U08GMN | GT1: A4M50R0414M | GU1: AC205 | GV1: AC2110 | GW1: AC2310 | GX1: AC2410 | GY1: AC2510 | GZ1: AC2610 | HA1: AC2710 | HB1: AC310 | HC1: AC403 | HD1: AC409 | HE1: AC410 | HF1: AC509 | HG1: AC513 | HH1: AC601 | HI1: AC602 | HJ1: AC604 | HK1: AC606 | HL1: AC608 | HM1: AC610 | HN1: AC612 | HO1: AC614 | HP1: AC701 | HQ1: AC702 | HR1: AC703 | HS1: AC704 | HT1: AC705 | HU1: AC707 | HV1: AC708 | HW1: AC710 | HX1: AC712 | HY1: AC715 | HZ1: AC717 | IA1: AC719 | IB1: AC727 | IC1: ANGT1623PPFR3LGJ | ID1: ASSTRINGS | IE1: BT-12340 | IF1: BT-12723 | IG1: BT-12804L | IH1: BT-12805L | II1: BT-1947-3 | IJ1: BT-4014-2-B | IK1: BT-4302-11.5P-3T | IL1: BT-4317-8P-4T | IM1: BT-5365-11P-3T | IN1: C10SCLPR2-4 | IO1: C10SCLPR3-7 | IP1: C12SCLPR3-4 | IQ1: C12SCLPR3-5 | IR1: C12SCLPR3-7 | IS1: C16SCLPR3-4 | IT1: C16SCLPR3-5 | IU1: C16SCLPR3-6 | IV1: C16SCLPR3-7 | IW1: C4SCLDR2 | IX1: CDCD-51-C25 | IY1: CNGP431 | IZ1: CNMG431 | JA1: CNMG432MLK10 | JB1: CNMS432 | JC1: CPMT2151LF | JD1: CPMT3250.5LF | JE1: CPMT3251LF | JF1: CPMT3252LF | JG1: CPMT3252LF-CAP | JH1: CT-11409 | JI1: CT-6002-17 | JJ1: CT-6002-3 | JK1: CT-6002-4 | JL1: CT-6003-13 | JM1: CT-6003-23 | JN1: CT-6003-24 | JO1: CT-6003-7 | JP1: CT-6004-19 | JQ1: CT-6004-2 | JR1: CT-6004-23 | JS1: CT-6004-24 | JT1: CT-6004-26 | JU1: CT-6004-27 | JV1: CT-6004-29 | JW1: CT-6004-37-NTX | JX1: CT-6004-40 | JY1: CT-6004-46 | JZ1: CT-6004-50 | KA1: CT-6004-6 | KB1: DA-LIVE-Z-HEAD | KC1: DCLNR164DKC | KD1: DGFH32-3 | KE1: DGNM-3202C | KF1: DPMT3251LF | KG1: DT-11628 | KH1: DT-11877 | KI1: DT-12680L | KJ1: DT-12724L | KK1: DT-12875L | KL1: DT-13131 | KM1: DT-13596 | KN1: DT-13596-A- | KO1: DT-13597 | KP1: DT-13885-NTX | KQ1: dt-13946L | KR1: DT-13949 | KS1: DVJNL163C | KT1: DVJNR163DKC3 | KU1: E16NER3 | KV1: E16SCLPR3 | KW1: E4M-SCLDR1.2 | KX1: ER32-COLLET | KY1: ER40-COLLET-SET | KZ1: EXTENSIONS | LA1: ISCAR-HAPR25.4C | LB1: ISCAR-HGAER-ADPT | LC1: ISCAR-HPGL-3003Y | LD1: ISCAR-SGTBU-CUTOFF | LE1: KGMSR1650N | LF1: KIPR125XD-ENDMILL | LG1: LIVE-X | LH1: LIVE-Z | LI1: LSASR16 | LJ1: LSASR163-LAYDN-THD | LK1: LSASR18 | LL1: LT16ER12UN | LM1: LT16ER16UN | LN1: LT16ER18UN | LO1: LTR.L.DRL | LP1: LTR.T.DRL | LQ1: MB-0393 | LR1: NG2031L | LS1: NG2047L | LT1: NG2062LK | LU1: NG2125LK | LV1: NG3047R | LW1: NG3062LK | LX1: NG3062R | LY1: NG3062RK | LZ1: NG3094RK | MA1: NG3125LK | MB1: NG3125RK | MC1: NO.05DRL | MD1: NO.10DRL | ME1: NO.21DRL | MF1: NO.23EXL-DRL | MG1: NO.27DRL | MH1: NO.30CBD-DRL | MI1: NO.41DRL | MJ1: NO.42DRL | MK1: NR3062L | ML1: NR3062R | MM1: NSL162C | MN1: NSL163C | MO1: NSR163C | MP1: NT3L | MQ1: NT3R | MR1: NTP2L | MS1: NTP3L | MT1: P-404-CONICAL | MU1: RJ1008 | MV1: RJ1010 | MW1: SOLID-ID-BLOCK | MX1: VNGP330.5 | MY1: VNMG332MP | MZ1: VNMS332 | NA1: VNMS-332 | NB1: CNMG431 | NC1: DCLNR164DKC | ND1: DGFH32-3 | NE1: DGNM-3202C | NF1: ISCAR-SGTBU-CUTOFF | NG1: ZT-COLLET-PADS | NH1: 1/4-2FL-CEM | NI1: 3/16SPOTDRL | NJ1: CNMS432 | NK1: DCLNR164DKC | NL1: LIVE-X | NM1: LIVE-Z | NN1: NO.30CBD-DRL | NO1: RJ1008
A2: 101759a | B2: =IF(Pivot!B6>0,1,0) -> 0 | C2: =IF(Pivot!C6>0,1,0) -> 0 | D2: =IF(Pivot!D6>0,1,0) -> 0 | E2: =IF(Pivot!E6>0,1,0) -> 0 | F2: =IF(Pivot!F6>0,1,0) -> 0 | G2: =IF(Pivot!G6>0,1,0) -> 0 | H2: =IF(Pivot!H6>0,1,0) -> 0 | I2: =IF(Pivot!I6>0,1,0) -> 0 | ... NO2: =IF(Pivot!NO6>0,1,0) -> 0
A3: 102088 | B3: =IF(Pivot!B7>0,1,0) -> 0 | C3: =IF(Pivot!C7>0,1,0) -> 0 | D3: =IF(Pivot!D7>0,1,0) -> 0 | E3: =IF(Pivot!E7>0,1,0) -> 0 | F3: =IF(Pivot!F7>0,1,0) -> 0 | G3: =IF(Pivot!G7>0,1,0) -> 0 | H3: =IF(Pivot!H7>0,1,0) -> 0 | I3: =IF(Pivot!I7>0,1,0) -> 0 | ... NO3: =IF(Pivot!NO7>0,1,0) -> 0
A4: 102097 | B4: =IF(Pivot!B8>0,1,0) -> 0 | C4: =IF(Pivot!C8>0,1,0) -> 0 | D4: =IF(Pivot!D8>0,1,0) -> 0 | E4: =IF(Pivot!E8>0,1,0) -> 0 | F4: =IF(Pivot!F8>0,1,0) -> 0 | G4: =IF(Pivot!G8>0,1,0) -> 0 | H4: =IF(Pivot!H8>0,1,0) -> 0 | I4: =IF(Pivot!I8>0,1,0) -> 0 | ... NO4: =IF(Pivot!NO8>0,1,0) -> 0
A5: 102258 | B5: =IF(Pivot!B9>0,1,0) -> 0 | C5: =IF(Pivot!C9>0,1,0) -> 0 | D5: =IF(Pivot!D9>0,1,0) -> 0 | E5: =IF(Pivot!E9>0,1,0) -> 0 | F5: =IF(Pivot!F9>0,1,0) -> 0 | G5: =IF(Pivot!G9>0,1,0) -> 0 | H5: =IF(Pivot!H9>0,1,0) -> 0 | I5: =IF(Pivot!I9>0,1,0) -> 0 | ... NO5: =IF(Pivot!NO9>0,1,0) -> 0
A6: 104403 | B6: =IF(Pivot!B10>0,1,0) -> 0 | C6: =IF(Pivot!C10>0,1,0) -> 0 | D6: =IF(Pivot!D10>0,1,0) -> 0 | E6: =IF(Pivot!E10>0,1,0) -> 0 | F6: =IF(Pivot!F10>0,1,0) -> 0 | G6: =IF(Pivot!G10>0,1,0) -> 0 | H6: =IF(Pivot!H10>0,1,0) -> 0 | I6: =IF(Pivot!I10>0,1,0) -> 0 | ... NO6: =IF(Pivot!NO10>0,1,0) -> 0
A7: 104430 | B7: =IF(Pivot!B11>0,1,0) -> 0 | C7: =IF(Pivot!C11>0,1,0) -> 0 | D7: =IF(Pivot!D11>0,1,0) -> 0 | E7: =IF(Pivot!E11>0,1,0) -> 0 | F7: =IF(Pivot!F11>0,1,0) -> 0 | G7: =IF(Pivot!G11>0,1,0) -> 0 | H7: =IF(Pivot!H11>0,1,0) -> 0 | I7: =IF(Pivot!I11>0,1,0) -> 0 | ... NO7: =IF(Pivot!NO11>0,1,0) -> 1
A8: 106939 | B8: =IF(Pivot!B12>0,1,0) -> 0 | C8: =IF(Pivot!C12>0,1,0) -> 0 | D8: =IF(Pivot!D12>0,1,0) -> 0 | E8: =IF(Pivot!E12>0,1,0) -> 0 | F8: =IF(Pivot!F12>0,1,0) -> 0 | G8: =IF(Pivot!G12>0,1,0) -> 0 | H8: =IF(Pivot!H12>0,1,0) -> 0 | I8: =IF(Pivot!I12>0,1,0) -> 1 | ... NO8: =IF(Pivot!NO12>0,1,0) -> 0
A9: 108314 | B9: =IF(Pivot!B13>0,1,0) -> 0 | C9: =IF(Pivot!C13>0,1,0) -> 0 | D9: =IF(Pivot!D13>0,1,0) -> 0 | E9: =IF(Pivot!E13>0,1,0) -> 0 | F9: =IF(Pivot!F13>0,1,0) -> 0 | G9: =IF(Pivot!G13>0,1,0) -> 0 | H9: =IF(Pivot!H13>0,1,0) -> 0 | I9: =IF(Pivot!I13>0,1,0) -> 1 | ... NO9: =IF(Pivot!NO13>0,1,0) -> 0
A10: 108354 | B10: =IF(Pivot!B14>0,1,0) -> 1 | C10: =IF(Pivot!C14>0,1,0) -> 0 | D10: =IF(Pivot!D14>0,1,0) -> 0 | E10: =IF(Pivot!E14>0,1,0) -> 0 | F10: =IF(Pivot!F14>0,1,0) -> 1 | G10: =IF(Pivot!G14>0,1,0) -> 0 | H10: =IF(Pivot!H14>0,1,0) -> 0 | I10: =IF(Pivot!I14>0,1,0) -> 1 | ... NO10: =IF(Pivot!NO14>0,1,0) -> 0
A11: 116344 | B11: =IF(Pivot!B15>0,1,0) -> 0 | C11: =IF(Pivot!C15>0,1,0) -> 0 | D11: =IF(Pivot!D15>0,1,0) -> 0 | E11: =IF(Pivot!E15>0,1,0) -> 0 | F11: =IF(Pivot!F15>0,1,0) -> 0 | G11: =IF(Pivot!G15>0,1,0) -> 0 | H11: =IF(Pivot!H15>0,1,0) -> 0 | I11: =IF(Pivot!I15>0,1,0) -> 0 | ... NO11: =IF(Pivot!NO15>0,1,0) -> 0
A12: 116811 | B12: =IF(Pivot!B16>0,1,0) -> 0 | C12: =IF(Pivot!C16>0,1,0) -> 0 | D12: =IF(Pivot!D16>0,1,0) -> 0 | E12: =IF(Pivot!E16>0,1,0) -> 0 | F12: =IF(Pivot!F16>0,1,0) -> 0 | G12: =IF(Pivot!G16>0,1,0) -> 0 | H12: =IF(Pivot!H16>0,1,0) -> 0 | I12: =IF(Pivot!I16>0,1,0) -> 0 | ... NO12: =IF(Pivot!NO16>0,1,0) -> 0
A13: 117425 | B13: =IF(Pivot!B17>0,1,0) -> 0 | C13: =IF(Pivot!C17>0,1,0) -> 0 | D13: =IF(Pivot!D17>0,1,0) -> 0 | E13: =IF(Pivot!E17>0,1,0) -> 0 | F13: =IF(Pivot!F17>0,1,0) -> 0 | G13: =IF(Pivot!G17>0,1,0) -> 0 | H13: =IF(Pivot!H17>0,1,0) -> 0 | I13: =IF(Pivot!I17>0,1,0) -> 0 | ... NO13: =IF(Pivot!NO17>0,1,0) -> 0
... A83: 127997 | B83: =IF(Pivot!B87>0,1,0) -> 0 | C83: =IF(Pivot!C87>0,1,0) -> 0 | D83: =IF(Pivot!D87>0,1,0) -> 0 | E83: =IF(Pivot!E87>0,1,0) -> 0 | F83: =IF(Pivot!F87>0,1,0) -> 0 | G83: =IF(Pivot!G87>0,1,0) -> 0 | H83: =IF(Pivot!H87>0,1,0) -> 0 | I83: =IF(Pivot!I87>0,1,0) -> 0 | ... NO83: =IF(Pivot!NO87>0,1,0) -> 0

Sheet Tool_Matrix
A1: Lables | B1: 101759a | C1: 102088 | D1: 102097 | E1: 102258 | F1: 104403 | G1: 104430 | H1: 106939 | I1: 108314 | J1: 108354 | K1: 116344 | L1: 116811 | M1: 117425 | N1: 117481 | O1: 118516 | P1: 118875 | Q1: 119400 | R1: 119887 | S1: 119927 | T1: 120308 | U1: 120337 | V1: 120522 | W1: 120698 | X1: 120699 | Y1: 120708 | Z1: 120709 | AA1: 120722 | AB1: 120730 | AC1: 120738 | AD1: 120739 | AE1: 120742 | AF1: 120744 | AG1: 120745 | AH1: 120996 | AI1: 121341 | AJ1: 122057 | AK1: 122174 | AL1: 122236 | AM1: 122276 | AN1: 124296 | AO1: 124329 | AP1: 124802 | AQ1: 124976 | AR1: 125771 | AS1: 125856 | AT1: 126099 | AU1: 126100 | AV1: 126736 | AW1: 126739 | AX1: 126763 | AY1: 126764 | AZ1: 127137 | BA1: 127142 | BB1: 127149 | BC1: 127184 | BD1: 127190 | BE1: 127215 | BF1: 127216 | BG1: 127223 | BH1: 127233 | BI1: 127262 | BJ1: 127264 | BK1: 127271 | BL1: 12728 | BM1: 127280 | BN1: 127322 | BO1: 127416 | BP1: 127441 | BQ1: 127449 | BR1: 127474 | BS1: 127492 | BT1: 127499 | BU1: 127511 | BV1: 127522 | BW1: 127530 | BX1: 127557 | BY1: 127589 | BZ1: 127652 | CA1: 127655 | CB1: 127678 | CC1: 127766 | CD1: 127919 | CE1: 127997
A2: 101759a | B2: 11 | C2: 5 | D2: 2 | E2: 2 | F2: 6 | G2: 0 | H2: 5 | I2: 2 | J2: 3 | K2: 4 | L2: 1 | M2: 6 | N2: 4 | O2: 5 | P2: 0 | Q2: 2 | R2: 5 | S2: 3 | T2: 5 | U2: 4 | V2: 4 | W2: 5 | X2: 5 | Y2: 5 | Z2: 5 | AA2: 5 | AB2: 5 | AC2: 5 | AD2: 5 | AE2: 5 | AF2: 5 | AG2: 5 | AH2: 5 | AI2: 6 | AJ2: 5 | AK2: 6 | AL2: 2 | AM2: 5 | AN2: 2 | AO2: 5 | AP2: 1 | AQ2: 4 | AR2: 1 | AS2: 2 | AT2: 2 | AU2: 2 | AV2: 3 | AW2: 5 | AX2: 2 | AY2: 2 | AZ2: 2 | BA2: 2 | BB2: 5 | BC2: 6 | BD2: 5 | BE2: 2 | BF2: 2 | BG2: 3 | BH2: 5 | BI2: 2 | BJ2: 5 | BK2: 4 | BL2: 2 | BM2: 2 | BN2: 0 | BO2: 5 | BP2: 4 | BQ2: 1 | BR2: 5 | BS2: 5 | BT2: 4 | BU2: 2 | BV2: 2 | BW2: 2 | BX2: 5 | BY2: 2 | BZ2: 1 | CA2: 4 | CB2: 1 | CC2: 1 | CD2: 4 | CE2: 4
A3: 102088 | B3: 5 | C3: 34 | D3: 18 | E3: 10 | F3: 8 | G3: 0 | H3: 11 | I3: 6 | J3: 5 | K3: 6 | L3: 6 | M3: 11 | N3: 9 | O3: 12 | P3: 3 | Q3: 5 | R3: 11 | S3: 4 | T3: 13 | U3: 8 | V3: 8 | W3: 15 | X3: 10 | Y3: 12 | Z3: 14 | AA3: 14 | AB3: 12 | AC3: 10 | AD3: 14 | AE3: 11 | AF3: 10 | AG3: 10 | AH3: 16 | AI3: 11 | AJ3: 13 | AK3: 13 | AL3: 10 | AM3: 14 | AN3: 8 | AO3: 14 | AP3: 8 | AQ3: 10 | AR3: 4 | AS3: 5 | AT3: 8 | AU3: 7 | AV3: 5 | AW3: 10 | AX3: 8 | AY3: 7 | AZ3: 9 | BA3: 8 | BB3: 10 | BC3: 11 | BD3: 11 | BE3: 6 | BF3: 8 | BG3: 9 | BH3: 10 | BI3: 5 | BJ3: 11 | BK3: 14 | BL3: 8 | BM3: 10 | BN3: 3 | BO3: 12 | BP3: 9 | BQ3: 6 | BR3: 12 | BS3: 14 | BT3: 12 | BU3: 8 | BV3: 8 | BW3: 7 | BX3: 12 | BY3: 7 | BZ3: 7 | CA3: 9 | CB3: 5 | CC3: 8 | CD3: 7 | CE3: 10
A4: 102097 | B4: 2 | C4: 18 | D4: 35 | E4: 7 | F4: 4 | G4: 0 | H4: 6 | I4: 5 | J4: 4 | K4: 2 | L4: 5 | M4: 4 | N4: 3 | O4: 6 | P4: 2 | Q4: 4 | R4: 6 | S4: 3 | T4: 6 | U4: 4 | V4: 4 | W4: 9 | X4: 5 | Y4: 6 | Z4: 8 | AA4: 9 | AB4: 6 | AC4: 5 | AD4: 9 | AE4: 6 | AF4: 5 | AG4: 5 | AH4: 10 | AI4: 4 | AJ4: 6 | AK4: 6 | AL4: 8 | AM4: 8 | AN4: 4 | AO4: 8 | AP4: 4 | AQ4: 4 | AR4: 4 | AS4: 4 | AT4: 5 | AU4: 5 | AV4: 4 | AW4: 5 | AX4: 5 | AY4: 5 | AZ4: 6 | BA4: 6 | BB4: 5 | BC4: 4 | BD4: 6 | BE4: 5 | BF4: 6 | BG4: 7 | BH4: 5 | BI4: 4 | BJ4: 6 | BK4: 9 | BL4: 7 | BM4: 7 | BN4: 2 | BO4: 6 | BP4: 3 | BQ4: 5 | BR4: 6 | BS4: 8 | BT4: 6 | BU4: 4 | BV4: 5 | BW4: 5 | BX4: 6 | BY4: 4 | BZ4: 6 | CA4: 3 | CB4: 3 | CC4: 5 | CD4: 3 | CE4: 4
A5: 102258 | B5: 2 | C5: 10 | D5: 7 | E5: 21 | F5: 5 | G5: 0 | H5: 7 | I5: 7 | J5: 6 | K5: 5 | L5: 8 | M5: 8 | N5: 4 | O5: 6 | P5: 4 | Q5: 6 | R5: 7 | S5: 4 | T5: 9 | U5: 6 | V5: 6 | W5: 12 | X5: 7 | Y5: 9 | Z5: 9 | AA5: 11 | AB5: 11 | AC5: 7 | AD5: 12 | AE5: 7 | AF5: 7 | AG5: 7 | AH5: 12 | AI5: 8 | AJ5: 9 | AK5: 8 | AL5: 8 | AM5: 9 | AN5: 6 | AO5: 9 | AP5: 6 | AQ5: 5 | AR5: 6 | AS5: 8 | AT5: 7 | AU5: 5 | AV5: 5 | AW5: 7 | AX5: 7 | AY5: 5 | AZ5: 10 | BA5: 10 | BB5: 7 | BC5: 8 | BD5: 7 | BE5: 7 | BF5: 7 | BG5: 8 | BH5: 7 | BI5: 8 | BJ5: 7 | BK5: 12 | BL5: 9 | BM5: 8 | BN5: 4 | BO5: 8 | BP5: 4 | BQ5: 8 | BR5: 9 | BS5: 9 | BT5: 9 | BU5: 6 | BV5: 7 | BW5: 5 | BX5: 6 | BY5: 6 | BZ5: 8 | CA5: 5 | CB5: 3 | CC5: 5 | CD5: 5 | CE5: 5
A6: 104403 | B6: 6 | C6: 8 | D6: 4 | E6: 5 | F6: 14 | G6: 0 | H6: 7 | I6: 3 | J6: 3 | K6: 5 | L6: 3 | M6: 8 | N6: 5 | O6: 8 | P6: 1 | Q6: 2 | R6: 8 | S6: 2 | T6: 7 | U6: 5 | V6: 5 | W6: 9 | X6: 6 | Y6: 10 | Z6: 10 | AA6: 9 | AB6: 7 | AC6: 6 | AD6: 9 | AE6: 8 | AF6: 6 | AG6: 6 | AH6: 9 | AI6: 8 | AJ6: 7 | AK6: 7 | AL6: 7 | AM6: 10 | AN6: 3 | AO6: 10 | AP6: 3 | AQ6: 5 | AR6: 4 | AS6: 4 | AT6: 4 | AU6: 3 | AV6: 4 | AW6: 6 | AX6: 4 | AY6: 3 | AZ6: 4 | BA6: 4 | BB6: 6 | BC6: 8 | BD6: 8 | BE6: 3 | BF6: 4 | BG6: 3 | BH6: 6 | BI6: 4 | BJ6: 8 | BK6: 8 | BL6: 4 | BM6: 3 | BN6: 1 | BO6: 6 | BP6: 5 | BQ6: 3 | BR6: 10 | BS6: 10 | BT6: 6 | BU6: 3 | BV6: 4 | BW6: 3 | BX6: 8 | BY6: 4 | BZ6: 3 | CA6: 4 | CB6: 1 | CC6: 1 | CD6: 5 | CE6: 5
A7: 104430 | B7: 0 | C7: 0 | D7: 0 | E7: 0 | F7: 0 | G7: 14 | H7: 0 | I7: 0 | J7: 0 | K7: 0 | L7: 0 | M7: 0 | N7: 0 | O7: 0 | P7: 0 | Q7: 0 | R7: 0 | S7: 0 | T7: 0 | U7: 0 | V7: 0 | W7: 0 | X7: 0 | Y7: 0 | Z7: 0 | AA7: 0 | AB7: 0 | AC7: 0 | AD7: 0 | AE7: 0 | AF7: 0 | AG7: 0 | AH7: 0 | AI7: 0 | AJ7: 0 | AK7: 0 | AL7: 0 | AM7: 0 | AN7: 0 | AO7: 0 | AP7: 0 | AQ7: 0 | AR7: 0 | AS7: 0 | AT7: 0 | AU7: 0 | AV7: 0 | AW7: 0 | AX7: 0 | AY7: 0 | AZ7: 0 | BA7: 0 | BB7: 0 | BC7: 0 | BD7: 0 | BE7: 0 | BF7: 0 | BG7: 0 | BH7: 0 | BI7: 0 | BJ7: 0 | BK7: 0 | BL7: 0 | BM7: 0 | BN7: 0 | BO7: 0 | BP7: 0 | BQ7: 0 | BR7: 0 | BS7: 0 | BT7: 0 | BU7: 0 | BV7: 0 | BW7: 0 | BX7: 0 | BY7: 0 | BZ7: 0 | CA7: 0 | CB7: 0 | CC7: 0 | CD7: 0 | CE7: 0
A8: 106939 | B8: 5 | C8: 11 | D8: 6 | E8: 7 | F8: 7 | G8: 0 | H8: 25 | I8: 12 | J8: 7 | K8: 7 | L8: 5 | M8: 11 | N8: 7 | O8: 11 | P8: 2 | Q8: 3 | R8: 12 | S8: 7 | T8: 12 | U8: 6 | V8: 6 | W8: 11 | X8: 16 | Y8: 11 | Z8: 10 | AA8: 13 | AB8: 8 | AC8: 16 | AD8: 10 | AE8: 13 | AF8: 16 | AG8: 11 | AH8: 13 | AI8: 11 | AJ8: 11 | AK8: 8 | AL8: 8 | AM8: 10 | AN8: 5 | AO8: 10 | AP8: 7 | AQ8: 7 | AR8: 3 | AS8: 4 | AT8: 6 | AU8: 7 | AV8: 5 | AW8: 9 | AX8: 6 | AY8: 7 | AZ8: 5 | BA8: 7 | BB8: 11 | BC8: 11 | BD8: 12 | BE8: 12 | BF8: 13 | BG8: 5 | BH8: 11 | BI8: 4 | BJ8: 13 | BK8: 10 | BL8: 5 | BM8: 8 | BN8: 2 | BO8: 7 | BP8: 7 | BQ8: 5 | BR8: 11 | BS8: 10 | BT8: 10 | BU8: 5 | BV8: 6 | BW8: 7 | BX8: 11 | BY8: 6 | BZ8: 5 | CA8: 6 | CB8: 2 | CC8: 5 | CD8: 6 | CE8: 7
A9: 108314 | B9: 2 | C9: 6 | D9: 5 | E9: 7 | F9: 3 | G9: 0 | H9: 12 | I9: 21 | J9: 8 | K9: 4 | L9: 6 | M9: 8 | N9: 3 | O9: 8 | P9: 2 | Q9: 3 | R9: 6 | S9: 6 | T9: 7 | U9: 4 | V9: 4 | W9: 6 | X9: 8 | Y9: 5 | Z9: 5 | AA9: 7 | AB9: 9 | AC9: 8 | AD9: 5 | AE9: 7 | AF9: 8 | AG9: 5 | AH9: 7 | AI9: 8 | AJ9: 7 | AK9: 5 | AL9: 6 | AM9: 5 | AN9: 5 | AO9: 5 | AP9: 6 | AQ9: 3 | AR9: 3 | AS9: 4 | AT9: 6 | AU9: 7 | AV9: 4 | AW9: 7 | AX9: 6 | AY9: 7 | AZ9: 5 | BA9: 6 | BB9: 5 | BC9: 8 | BD9: 6 | BE9: 21 | BF9: 14 | BG9: 7 | BH9: 5 | BI9: 4 | BJ9: 7 | BK9: 6 | BL9: 6 | BM9: 8 | BN9: 2 | BO9: 5 | BP9: 3 | BQ9: 6 | BR9: 5 | BS9: 5 | BT9: 7 | BU9: 5 | BV9: 6 | BW9: 7 | BX9: 8 | BY9: 6 | BZ9: 7 | CA9: 4 | CB9: 1 | CC9: 4 | CD9: 4 | CE9: 3
A10: 108354 | B10: 3 | C10: 5 | D10: 4 | E10: 6 | F10: 3 | G10: 0 | H10: 7 | I10: 8 | J10: 22 | K10: 2 | L10: 2 | M10: 5 | N10: 3 | O10: 5 | P10: 1 | Q10: 3 | R10: 4 | S10: 5 | T10: 6 | U10: 3 | V10: 3 | W10: 6 | X10: 5 | Y10: 6 | Z10: 6 | AA10: 6 | AB10: 5 | AC10: 5 | AD10: 6 | AE10: 4 | AF10: 5 | AG10: 3 | AH10: 6 | AI10: 5 | AJ10: 6 | AK10: 4 | AL10: 6 | AM10: 6 | AN10: 5 | AO10: 6 | AP10: 7 | AQ10: 3 | AR10: 3 | AS10: 7 | AT10: 4 | AU10: 3 | AV10: 7 | AW10: 6 | AX10: 4 | AY10: 3 | AZ10: 5 | BA10: 6 | BB10: 3 | BC10: 5 | BD10: 4 | BE10: 8 | BF10: 8 | BG10: 6 | BH10: 3 | BI10: 7 | BJ10: 4 | BK10: 6 | BL10: 5 | BM10: 6 | BN10: 1 | BO10: 4 | BP10: 3 | BQ10: 2 | BR10: 6 | BS10: 6 | BT10: 6 | BU10: 5 | BV10: 4 | BW10: 3 | BX10: 5 | BY10: 5 | BZ10: 2 | CA10: 3 | CB10: 1 | CC10: 3 | CD10: 3 | CE10: 3
A11: 116344 | B11: 4 | C11: 6 | D11: 2 | E11: 5 | F11: 5 | G11: 0 | H11: 7 | I11: 4 | J11: 2 | K11: 22 | L11: 6 | M11: 10 | N11: 4 | O11: 5 | P11: 5 | Q11: 3 | R11: 7 | S11: 4 | T11: 5 | U11: 11 | V11: 11 | W11: 9 | X11: 7 | Y11: 7 | Z11: 7 | AA11: 10 | AB11: 10 | AC11: 7 | AD11: 8 | AE11: 7 | AF11: 7 | AG11: 11 | AH11: 10 | AI11: 10 | AJ11: 5 | AK11: 10 | AL11: 3 | AM11: 7 | AN11: 3 | AO11: 7 | AP11: 2 | AQ11: 4 | AR11: 8 | AS11: 2 | AT11: 2 | AU11: 4 | AV11: 2 | AW11: 5 | AX11: 2 | AY11: 4 | AZ11: 4 | BA11: 5 | BB11: 11 | BC11: 10 | BD11: 7 | BE11: 4 | BF11: 2 | BG11: 5 | BH11: 11 | BI11: 2 | BJ11: 7 | BK11: 8 | BL11: 6 | BM11: 3 | BN11: 5 | BO11: 9 | BP11: 4 | BQ11: 6 | BR11: 7 | BS11: 7 | BT11: 4 | BU11: 3 | BV11: 2 | BW11: 4 | BX11: 5 | BY11: 3 | BZ11: 6 | CA11: 4 | CB11: 4 | CC11: 1 | CD11: 15 | CE11: 4
A12: 116811 | B12: 1 | C12: 6 | D12: 5 | E12: 8 | F12: 3 | G12: 0 | H12: 5 | I12: 6 | J12: 2 | K12: 6 | L12: 27 | M12: 7 | N12: 4 | O12: 6 | P12: 4 | Q12: 5 | R12: 5 | S12: 3 | T12: 4 | U12: 8 | V12: 8 | W12: 7 | X12: 5 | Y12: 6 | Z12: 5 | AA12: 6 | AB12: 9 | AC12: 5 | AD12: 6 | AE12: 5 | AF12: 5 | AG12: 5 | AH12: 7 | AI12: 7 | AJ12: 4 | AK12: 5 | AL12: 8 | AM12: 5 | AN12: 3 | AO12: 5 | AP12: 3 | AQ12: 6 | AR12: 7 | AS12: 4 | AT12: 6 | AU12: 4 | AV12: 3 | AW12: 4 | AX12: 6 | AY12: 4 | AZ12: 6 | BA12: 6 | BB12: 5 | BC12: 7 | BD12: 5 | BE12: 6 | BF12: 5 | BG12: 8 | BH12: 5 | BI12: 4 | BJ12: 5 | BK12: 7 | BL12: 7 | BM12: 5 | BN12: 4 | BO12: 5 | BP12: 4 | BQ12: 27 | BR12: 6 | BS12: 5 | BT12: 4 | BU12: 3 | BV12: 6 | BW12: 4 | BX12: 6 | BY12: 4 | BZ12: 25 | CA12: 3 | CB12: 5 | CC12: 5 | CD12: 8 | CE12: 6
A13: 117425 | B13: 6 | C13: 11 | D13: 4 | E13: 8 | F13: 8 | G13: 0 | H13: 11 | I13: 8 | J13: 5 | K13: 10 | L13: 7 | M13: 25 | N13: 6 | O13: 11 | P13: 5 | Q13: 4 | R13: 11 | S13: 6 | T13: 12 | U13: 9 | V13: 9 | W13: 15 | X13: 10 | Y13: 12 | Z13: 12 | AA13: 12 | AB13: 11 | AC13: 10 | AD13: 12 | AE13: 11 | AF13: 10 | AG13: 9 | AH13: 14 | AI13: 25 | AJ13: 12 | AK13: 18 | AL13: 7 | AM13: 12 | AN13: 5 | AO13: 12 | AP13: 5 | AQ13: 6 | AR13: 5 | AS13: 4 | AT13: 8 | AU13: 6 | AV13: 5 | AW13: 10 | AX13: 8 | AY13: 6 | AZ13: 7 | BA13: 7 | BB13: 9 | BC13: 25 | BD13: 11 | BE13: 8 | BF13: 8 | BG13: 11 | BH13: 9 | BI13: 4 | BJ13: 11 | BK13: 14 | BL13: 7 | BM13: 7 | BN13: 5 | BO13: 17 | BP13: 6 | BQ13: 7 | BR13: 12 | BS13: 12 | BT13: 11 | BU13: 5 | BV13: 8 | BW13: 6 | BX13: 11 | BY13: 8 | BZ13: 7 | CA13: 6 | CB13: 4 | CC13: 4 | CD13: 9 | CE13: 6
... A83: 127997 | B83: 4 | C83: 10 | D83: 4 | E83: 5 | F83: 5 | G83: 0 | H83: 7 | I83: 3 | J83: 3 | K83: 4 | L83: 6 | M83: 6 | N83: 23 | O83: 8 | P83: 3 | Q83: 6 | R83: 6 | S83: 5 | T83: 10 | U83: 4 | V83: 4 | W83: 9 | X83: 7 | Y83: 11 | Z83: 11 | AA83: 8 | AB83: 7 | AC83: 7 | AD83: 11 | AE83: 6 | AF83: 7 | AG83: 6 | AH83: 10 | AI83: 6 | AJ83: 10 | AK83: 7 | AL83: 11 | AM83: 11 | AN83: 6 | AO83: 11 | AP83: 7 | AQ83: 26 | AR83: 1 | AS83: 5 | AT83: 5 | AU83: 5 | AV83: 4 | AW83: 6 | AX83: 5 | AY83: 5 | AZ83: 5 | BA83: 6 | BB83: 6 | BC83: 6 | BD83: 6 | BE83: 3 | BF83: 5 | BG83: 3 | BH83: 6 | BI83: 5 | BJ83: 6 | BK83: 8 | BL83: 5 | BM83: 5 | BN83: 3 | BO83: 6 | BP83: 23 | BQ83: 6 | BR83: 11 | BS83: 11 | BT83: 9 | BU83: 6 | BV83: 5 | BW83: 5 | BX83: 8 | BY83: 4 | BZ83: 4 | CA83: 21 | CB83: 5 | CC83: 10 | CD83: 5 | CE83: 26

Sheet 697
A1: ItemNumber | B1: Operation | C1: WorkCenter | D1: ChuckingNumber | E1: ProgramNumber | F1: Notes | G1: ToolID | H1: ToolNumber | I1: Description | J1: Turret | K1: StationNumber
A2: 120308 | B2: 25 | C2: 320697 | D2: 1 | E2: 8567-R7 | F2: Chuck Pressure Main: 80 LBS. AIR Chuck Pressure Sub: 200 LBS. Pusher Rod Size: LARGE Bar Pusher Length: 4.65 Pusher Disc Diameter: 2.0 Spindle Reduction Liner: 3.25 Top Cut Position: .5 Face of Fed Out Bar: 5.15 FACE & TURN, OD GROOVE, BORE, ID GROOVE, LX CAM GROOVE LX SPOT & DRILL, DEBURR PASSES, PART OFF | G2: 18086 | H2: CNMS432 | I2: CNMS432 | J2: UPPER | K2: 1
A3: 120308 | B3: 25 | C3: 320697 | D3: 1 | E3: 8567-R7 | F3: Chuck Pressure Main: 80 LBS. AIR Chuck Pressure Sub: 200 LBS. Pusher Rod Size: LARGE Bar Pusher Length: 4.65 Pusher Disc Diameter: 2.0 Spindle Reduction Liner: 3.25 Top Cut Position: .5 Face of Fed Out Bar: 5.15 FACE & TURN, OD GROOVE, BORE, ID GROOVE, LX CAM GROOVE LX SPOT & DRILL, DEBURR PASSES, PART OFF | G3: 18087 | H3: NSR163C | I3: 5 IN. LONG SIZE 3 INSERT 5 IN. LONG | J3: UPPER | K3: 2
A4: 120308 | B4: 25 | C4: 320697 | D4: 1 | E4: 8567-R7 | F4: Chuck Pressure Main: 80 LBS. AIR Chuck Pressure Sub: 200 LBS. Pusher Rod Size: LARGE Bar Pusher Length: 4.65 Pusher Disc Diameter: 2.0 Spindle Reduction Liner: 3.25 Top Cut Position: .5 Face of Fed Out Bar: 5.15 FACE & TURN, OD GROOVE, BORE, ID GROOVE, LX CAM GROOVE LX SPOT & DRILL, DEBURR PASSES, PART OFF | G4: 18088 | H4: NG3062RK | I4: KC 730 .062 OD GROOVE INSERT CONSIGNED 1-11-05 | J4: UPPER | K4: 2
A5: 120308 | B5: 25 | C5: 320697 | D5: 1 | E5: 8567-R7 | F5: Chuck Pressure Main: 80 LBS. AIR Chuck Pressure Sub: 200 LBS. Pusher Rod Size: LARGE Bar Pusher Length: 4.65 Pusher Disc Diameter: 2.0 Spindle Reduction Liner: 3.25 Top Cut Position: .5 Face of Fed Out Bar: 5.15 FACE & TURN, OD GROOVE, BORE, ID GROOVE, LX CAM GROOVE LX SPOT & DRILL, DEBURR PASSES, PART OFF | G5: 18089 | H5: C16SCLPR3-5 | I5: C16SCLPR3-5 (1.00) CBB 5 OAL 1 X 5 OAL | J5: UPPER | K5: 3
A6: 120308 | B6: 25 | C6: 320697 | D6: 1 | E6: 8567-R7 | F6: Chuck Pressure Main: 80 LBS. AIR Chuck Pressure Sub: 200 LBS. Pusher Rod Size: LARGE Bar Pusher Length: 4.65 Pusher Disc Diameter: 2.0 Spindle Reduction Liner: 3.25 Top Cut Position: .5 Face of Fed Out Bar: 5.15 FACE & TURN, OD GROOVE, BORE, ID GROOVE, LX CAM GROOVE LX SPOT & DRILL, DEBURR PASSES, PART OFF | G6: 18090 | H6: CPMT3252LF | I6: KC5010 .031 RAD. 80 DEG. INSERT CONSIGNED 10-8-04 | J6: UPPER | K6: 3
A7: 120308 | B7: 25 | C7: 320697 | D7: 1 | E7: 8567-R7 | F7: Chuck Pressure Main: 80 LBS. AIR Chuck Pressure Sub: 200 LBS. Pusher Rod Size: LARGE Bar Pusher Length: 4.65 Pusher Disc Diameter: 2.0 Spindle Reduction Liner: 3.25 Top Cut Position: .5 Face of Fed Out Bar: 5.15 FACE & TURN, OD GROOVE, BORE, ID GROOVE, LX CAM GROOVE LX SPOT & DRILL, DEBURR PASSES, PART OFF | G7: 18091 | H7: A16NER3 | I7: 1" STUBBY STEEL GRV / THD 1'' SGB | J7: UPPER | K7: 7
A8: 120308 | B8: 25 | C8: 320697 | D8: 1 | E8: 8567-R7 | F8: Chuck Pressure Main: 80 LBS. AIR Chuck Pressure Sub: 200 LBS. Pusher Rod Size: LARGE Bar Pusher Length: 4.65 Pusher Disc Diameter: 2.0 Spindle Reduction Liner: 3.25 Top Cut Position: .5 Face of Fed Out Bar: 5.15 FACE & TURN, OD GROOVE, BORE, ID GROOVE, LX CAM GROOVE LX SPOT & DRILL, DEBURR PASSES, PART OFF | G8: 18092 | H8: NG3062LK | I8: KC 730 .062 ID GROOVE INSERT CONSIGNED 10/29/04 | J8: UPPER | K8: 7
A9: 120308 | B9: 25 | C9: 320697 | D9: 1 | E9: 8567-R7 | F9: Chuck Pressure Main: 80 LBS. AIR Chuck Pressure Sub: 200 LBS. Pusher Rod Size: LARGE Bar Pusher Length: 4.65 Pusher Disc Diameter: 2.0 Spindle Reduction Liner: 3.25 Top Cut Position: .5 Face of Fed Out Bar: 5.15 FACE & TURN, OD GROOVE, BORE, ID GROOVE, LX CAM GROOVE LX SPOT & DRILL, DEBURR PASSES, PART OFF | G9: 18093 | H9: LIVE-X | I9: HEAD | J9: UPPER | K9: 4
A10: 120308 | B10: 25 | C10: 320697 | D10: 1 | E10: 8567-R7 | F10: Chuck Pressure Main: 80 LBS. AIR Chuck Pressure Sub: 200 LBS. Pusher Rod Size: LARGE Bar Pusher Length: 4.65 Pusher Disc Diameter: 2.0 Spindle Reduction Liner: 3.25 Top Cut Position: .5 Face of Fed Out Bar: 5.15 FACE & TURN, OD GROOVE, BORE, ID GROOVE, LX CAM GROOVE LX SPOT & DRILL, DEBURR PASSES, PART OFF | G10: 18094 | H10: LIVE-X | I10: HEAD | J10: UPPER | K10: 9
A11: 120308 | B11: 25 | C11: 320697 | D11: 1 | E11: 8567-R7 | F11: Chuck Pressure Main: 80 LBS. AIR Chuck Pressure Sub: 200 LBS. Pusher Rod Size: LARGE Bar Pusher Length: 4.65 Pusher Disc Diameter: 2.0 Spindle Reduction Liner: 3.25 Top Cut Position: .5 Face of Fed Out Bar: 5.15 FACE & TURN, OD GROOVE, BORE, ID GROOVE, LX CAM GROOVE LX SPOT & DRILL, DEBURR PASSES, PART OFF | G11: 18096 | H11: ER40-COLLET-SET | I11: ER40-COLLET-SET ASSORTED SIZES | J11: UPPER | K11: 4
A12: 120308 | B12: 25 | C12: 320697 | D12: 1 | E12: 8567-R7 | F12: Chuck Pressure Main: 80 LBS. AIR Chuck Pressure Sub: 200 LBS. Pusher Rod Size: LARGE Bar Pusher Length: 4.65 Pusher Disc Diameter: 2.0 Spindle Reduction Liner: 3.25 Top Cut Position: .5 Face of Fed Out Bar: 5.15 FACE & TURN, OD GROOVE, BORE, ID GROOVE, LX CAM GROOVE LX SPOT & DRILL, DEBURR PASSES, PART OFF | G12: 18097 | H12: ER40-COLLET-SET | I12: ER40-COLLET-SET ASSORTED SIZES | J12: UPPER | K12: 9
A13: 120308 | B13: 25 | C13: 320697 | D13: 1 | E13: 8567-R7 | F13: Chuck Pressure Main: 80 LBS. AIR Chuck Pressure Sub: 200 LBS. Pusher Rod Size: LARGE Bar Pusher Length: 4.65 Pusher Disc Diameter: 2.0 Spindle Reduction Liner: 3.25 Top Cut Position: .5 Face of Fed Out Bar: 5.15 FACE & TURN, OD GROOVE, BORE, ID GROOVE, LX CAM GROOVE LX SPOT & DRILL, DEBURR PASSES, PART OFF | G13: 18098 | H13: ER40-COLLET-SET | I13: ER40-COLLET-SET ASSORTED SIZES | J13: UPPER | K13: 10
... A2004: 127216 | B2004: 30 | C2004: 320697 | D2004: 1 | E2004: 8146-R7 | F2004: Chuck Pressure Main: 80 air Chuck Pressure Sub: 150 lbs Pusher Rod Size: lg Bar Pusher Length: 1.215 Pusher Disc Diameter: 1.5" Spindle Reduction Liner: 3.25 Top Cut Position: .5 | G2004: 72509 | H2004: DCLNR164DKC | I2004: 80*TURN TOOL /DCLNR164DKC;6" O.A.L. | J2004: UPPER | K2004: 1
A2005: 127216 | B2005: 30 | C2005: 320697 | D2005: 2 | E2005: 8147-R7 | G2005: 73347 | H2005: CT-6004-27 | I2005: LOCATOR;2.600 X 2.490 // 6004-50 | J2005: WORK HOLD | K2005: 0
A2006: 127216 | B2006: 30 | C2006: 320697 | D2006: 2 | E2006: 8147-R7 | G2006: 72522 | H2006: AC2710 | I2006: AC2710 WW ARBOR | J2006: WORK HOLD | K2006: 0
A2007: 127216 | B2007: 30 | C2007: 320697 | D2007: 2 | E2007: 8147-R7 | G2007: 72523 | H2007: AC707 | I2007: AC707 2.125-2.155 | J2007: WORK HOLD | K2007: 0
A2008: 127216 | B2008: 30 | C2008: 320697 | D2008: 2 | E2008: 8147-R7 | G2008: 72525 | H2008: DCLNR164DKC | I2008: 80*TURN TOOL /DCLNR164DKC;6" O.A.L. | J2008: LOWER | K2008: 31
A2009: 127216 | B2009: 30 | C2009: 320697 | D2009: 2 | E2009: 8147-R7 | G2009: 72526 | H2009: CNMS432 | I2009: CNMS432 | J2009: LOWER | K2009: 31
A2010: 127216 | B2010: 30 | C2010: 320697 | D2010: 2 | E2010: 8147-R7 | G2010: 72527 | H2010: C16SCLPR3-7 | I2010: BORE BAR 1" C16SCLPR3 STUBBY | J2010: LOWER | K2010: 33
A2011: 127216 | B2011: 30 | C2011: 320697 | D2011: 2 | E2011: 8147-R7 | G2011: 72528 | H2011: CPMT3252LF | I2011: CPMT3252LF | J2011: LOWER | K2011: 33
A2012: 127216 | B2012: 30 | C2012: 320697 | D2012: 2 | E2012: 8147-R7 | G2012: 72529 | H2012: LIVE-Z | I2012: HEAD | J2012: UPPER | K2012: 35
A2013: 127216 | B2013: 30 | C2013: 320697 | D2013: 2 | E2013: 8147-R7 | G2013: 72530 | H2013: BT-5365-11P-3T | I2013: 11 PITCH 3 TOOTH BSP | J2013: UPPER | K2013: 35
A2014: 127652 | B2014: 35 | C2014: 320697 | D2014: 1 | E2014: 8162-R7 | F2014: Chuck Pressure Main: 80 air Chuck Pressure Sub: 175 Pusher Rod Size: LG Bar Pusher Length: 3.975 Pusher Disc Diameter: 2. Spindle Reduction Liner: 3.25 Top Cut Position: .5 Face of Fed Out Bar: 4.475 Face of Cut Off Bar:.375 | G2014: 72846 | H2014: DVJNL163C | I2014: 35* LEFT HAND | J2014: LOWER | K2014: 2
A2015: 127652 | B2015: 35 | C2015: 320697 | D2015: 1 | E2015: 8162-R7 | F2015: Chuck Pressure Main: 80 air Chuck Pressure Sub: 175 Pusher Rod Size: LG Bar Pusher Length: 3.975 Pusher Disc Diameter: 2. Spindle Reduction Liner: 3.25 Top Cut Position: .5 Face of Fed Out Bar: 4.475 Face of Cut Off Bar:.375 | G2015: 72852 | H2015: 59/64-SPADE-INS | I2015: 59/64" (.921) SPADE BLADE | J2015: LOWER | K2015: 12
A2016: 127652 | B2016: 35 | C2016: 320697 | D2016: 1 | E2016: 8162-R7 | F2016: Chuck Pressure Main: 80 air Chuck Pressure Sub: 175 Pusher Rod Size: LG Bar Pusher Length: 3.975 Pusher Disc Diameter: 2. Spindle Reduction Liner: 3.25 Top Cut Position: .5 Face of Fed Out Bar: 4.475 Face of Cut Off Bar:.375 | G2016: 72853 | H2016: A12NER2 | I2016: 3/4" ID GROOVE RH 10" STEEL | J2016: UPPER | K2016: 7
A2017: 127652 | B2017: 35 | C2017: 320697 | D2017: 1 | E2017: 8162-R7 | F2017: Chuck Pressure Main: 80 air Chuck Pressure Sub: 175 Pusher Rod Size: LG Bar Pusher Length: 3.975 Pusher Disc Diameter: 2. Spindle Reduction Liner: 3.25 Top Cut Position: .5 Face of Fed Out Bar: 4.475 Face of Cut Off Bar:.375 | G2017: 72854 | H2017: NG3094LK KC5010 | I2017: NG3094LK KC5010 TOP NOTCH GROOVING INSERT | J2017: UPPER | K2017: 7
A2018: 127652 | B2018: 35 | C2018: 320697 | D2018: 1 | E2018: 8162-R7 | F2018: Chuck Pressure Main: 80 air Chuck Pressure Sub: 175 Pusher Rod Size: LG Bar Pusher Length: 3.975 Pusher Disc Diameter: 2. Spindle Reduction Liner: 3.25 Top Cut Position: .5 Face of Fed Out Bar: 4.475 Face of Cut Off Bar:.375 | G2018: 72855 | H2018: A12NER2 | I2018: 3/4" ID GROOVE RH 10" STEEL | J2018: UPPER | K2018: 9
A2019: 127652 | B2019: 35 | C2019: 320697 | D2019: 1 | E2019: 8162-R7 | F2019: Chuck Pressure Main: 80 air Chuck Pressure Sub: 175 Pusher Rod Size: LG Bar Pusher Length: 3.975 Pusher Disc Diameter: 2. Spindle Reduction Liner: 3.25 Top Cut Position: .5 Face of Fed Out Bar: 4.475 Face of Cut Off Bar:.375 | G2019: 72856 | H2019: NTP2L | I2019: NTP2L KC5010 TOP NOTCH THREADING INS | J2019: UPPER | K2019: 9
A2020: 127652 | B2020: 35 | C2020: 320697 | D2020: 1 | E2020: 8162-R7 | F2020: Chuck Pressure Main: 80 air Chuck Pressure Sub: 175 Pusher Rod Size: LG Bar Pusher Length: 3.975 Pusher Disc Diameter: 2. Spindle Reduction Liner: 3.25 Top Cut Position: .5 Face of Fed Out Bar: 4.475 Face of Cut Off Bar:.375 | G2020: 72857 | H2020: MCHR-506-101-20 | I2020: 1/8 MANCHESTER PART OFF INSERT .125 | J2020: UPPER | K2020: 12
A2021: 127652 | B2021: 35 | C2021: 320697 | D2021: 1 | E2021: 8162-R7 | F2021: Chuck Pressure Main: 80 air Chuck Pressure Sub: 175 Pusher Rod Size: LG Bar Pusher Length: 3.975 Pusher Disc Diameter: 2. Spindle Reduction Liner: 3.25 Top Cut Position: .5 Face of Fed Out Bar: 4.475 Face of Cut Off Bar:.375 | G2021: 72858 | H2021: MCHR-507-231-33 | I2021: 1/8 MANCHESTER PART OFF INSERT (.125) | J2021: UPPER | K2021: 12
A2022: 127652 | B2022: 35 | C2022: 320697 | D2022: 1 | E2022: 8162-R7 | F2022: Chuck Pressure Main: 80 air Chuck Pressure Sub: 175 Pusher Rod Size: LG Bar Pusher Length: 3.975 Pusher Disc Diameter: 2. Spindle Reduction Liner: 3.25 Top Cut Position: .5 Face of Fed Out Bar: 4.475 Face of Cut Off Bar:.375 | G2022: 72859 | H2022: 10PITCHKNURL | I2022: POST TOOL;DORIAN HOLDER+10 PITCH WHEELS | J2022: UPPER | K2022: 6
A2023: 127652 | B2023: 35 | C2023: 320697 | D2023: 1 | E2023: 8162-R7 | F2023: Chuck Pressure Main: 80 air Chuck Pressure Sub: 175 Pusher Rod Size: LG Bar Pusher Length: 3.975 Pusher Disc Diameter: 2. Spindle Reduction Liner: 3.25 Top Cut Position: .5 Face of Fed Out Bar: 4.475 Face of Cut Off Bar:.375 | G2023: 72851 | H2023: 23010S-100L-SPADE | I2023: 23010S-100L SERIES 1 HLDR SPADE;4.750 FLUTE LENGTH | J2023: LOWER | K2023: 12
A2024: 127652 | B2024: 35 | C2024: 320697 | D2024: 1 | E2024: 8162-R7 | F2024: Chuck Pressure Main: 80 air Chuck Pressure Sub: 175 Pusher Rod Size: LG Bar Pusher Length: 3.975 Pusher Disc Diameter: 2. Spindle Reduction Liner: 3.25 Top Cut Position: .5 Face of Fed Out Bar: 4.475 Face of Cut Off Bar:.375 | G2024: 72849 | H2024: CPMT3252LF | I2024: CPMT3252LF KC5010 KMT TURNING INSERT | J2024: UPPER | K2024: 3
A2025: 127652 | B2025: 35 | C2025: 320697 | D2025: 1 | E2025: 8162-R7 | F2025: Chuck Pressure Main: 80 air Chuck Pressure Sub: 175 Pusher Rod Size: LG Bar Pusher Length: 3.975 Pusher Disc Diameter: 2. Spindle Reduction Liner: 3.25 Top Cut Position: .5 Face of Fed Out Bar: 4.475 Face of Cut Off Bar:.375 | G2025: 72850 | H2025: SOLID-ID-BLOCK | I2025: SOLID BLOCK FOR ID TOOLS | J2025: LOWER | K2025: 12
... A2251: 101759a | B2251: 10 | C2251: 320697 | D2251: 1 | E2251: 8140-R7 | F2251: Chuck Pressure Main: 80* AIR Chuck Pressure Sub: 175 LBS Pusher Rod Size: LG Bar Pusher Length: .738 Pusher Disc Diameter: 2.0 Spindle Reduction Liner: 3.25 Top Cut Position: .500 ** USE ID ROBOT JAWS ON SETTING #2 ** SET ROBOT TO GRIP OD ** | G2251: 92301 | H2251: ISCAR-SGTBU-CUTOFF | I2251: POST TOOL ISCAR CUTOFF | J2251: UPPER | K2251: 12
A2252: 101759a | B2252: 10 | C2252: 320697 | D2252: 2 | E2252: 8141-R7 | G2252: 81493 | H2252: DCLNR164DKC | I2252: 80*TURN TOOL /DCLNR164DKC;6" O.A.L. | J2252: LOWER | K2252: 31
A2253: 101759a | B2253: 10 | C2253: 320697 | D2253: 2 | E2253: 8141-R7 | G2253: 81494 | H2253: CNGP431 | I2253: CNGP431 KC5010 KENLOC TURNING INSERT | J2253: LOWER | K2253: 31
A2254: 101759a | B2254: 10 | C2254: 320697 | D2254: 2 | E2254: 8141-R7 | G2254: 81495 | H2254: 3/16SPOTDRL | I2254: .187 SPOT DRILL | J2254: LOWER | K2254: 38
A2255: 101759a | B2255: 10 | C2255: 320697 | D2255: 2 | E2255: 8141-R7 | G2255: 81496 | H2255: NO.27DRL | I2255: #27 DRILL.144 | J2255: LOWER | K2255: 36
...
